  <!DOCTYPE html>
<html lang="en">
<head>
  <meta charset="UTF-8">
  <title>Async practice</title>
  <link rel="stylesheet" href="https://stackpath.bootstrapcdn.com/bootstrap/4.3.1/css/bootstrap.min.css" integrity="sha384-ggOyR0iXCbMQv3Xipma34MD+dH/1fQ784/j6cY/iJTQUOhcWr7x9JvoRxT2MZw1T" crossorigin="anonymous">
  <style>
    body { padding-top: 50px; }    
  </style>
</head>
<!--   <script src="/sample.js"></script> -->

  <body>


    <input  onkeydown=check(event)  />

<script>




// We'll start with some callbacks
  // console.log("Its wirking");



  


  // loadScript('/sample.js'); // Hoisting bitches!!
  // console.log(checkerFunction()); // This throws a not defined error
  // How do we fix this?
  // Callbacks!!!
  // function loadScript(src,callback){
  //   let script = document.createElement('script');
  //   // console.log("This runs")
  //   script.src=src;
  //   // console.log("this also runs")
  //   script.onload = () => callback(script);
    
  //   document.head.append(script);
  //   // console.log("this does not run")
    
  // }

  // console.log(loadScript('/sample.js'));
  // loadScript('/sample.js',()=>alert("kameshwar"));
  
//   loadScript('https://cdnjs.cloudflare.com/ajax/libs/lodash.js/3.2.0/lodash.js', script => {
//   alert(`Cool, the script ${script.src} is loaded`);
//   alert( _ ); // _ is a function declared in the loaded script
// });

  // What if we want to load multiple scripts?

  // One way to do this is the callback inside a callback method
  // loadScript('/sample.js',()=>{
  //   alert("Sample.js has been loaded");
  //   loadScript("/sample2.js",()=>{
  //     alert("sample2.js has been loaded");
  //     loadScript("/sample3.js",()=>{
  //       alert("sample3 has laoded");
  //     })
  //   })
  // })
  // In the above function we are nesting callbacks in a way that call backs run till one particular callback fails
  // All callbacks run only when none of them fail. So we have chained our call backs
  // This is fine upto a certain point but we will run into fuck all problems when we reach a higher
  // degree of complexity.
  // We should avoid doing this. Let's check out some alternatives.


  // Lets look at how errors are handled for aynchronous functions
   function loadScript(src,callback){
    let script = document.createElement('script');
    // console.log("This runs")
    script.src=src;
    // console.log("this also runs")
    script.onload = () => callback(null,script);
    script.onerror = () => callback(new Error(`Script load error for ${src}`))
    
    document.head.append(script);
    // console.log("this does not run")
    
  }


  // This apparently forms the pyramid of doom.
  // They have provided another method to deal with this which seperates out everycall back
  // I dont know why it looks like syntactic sugar.
  // loadScript('/sample.js',(error,script)=>{
  //   if(error){
  //     console.log(error);
  //   }else{
  //     loadScript("/sample2.js",(error,script)=>{
  //       if(error){
  //         console.log(error);
  //       }else{
  //         loadScript("/sample3.js",(error,script)=>{
  //           if(error){
  //             console.log(error);
  //           }else{
  //             console.log("All is working well")
  //           }
  //         })
  //       }
  //     })
  //   }
  // })

  // loadScript("/sample.js",step1);
  // function step1(error,script){
  //   if (error){
  //     console.log(error);
  //   }
  //   else loadScript('/script2.js',step2)
  // }


  // function step2(error,script){
  //   if (error){
  //     console.log(error);
  //   }
  //   else loadScript('/script3.js',step2)
  // }


  // Both the above methods are exactly the same. The below method just provides some syntactic sugar.
  
  


  // Lets work on some promises
  // The construction syntax for a promise object is 
  // let promise = new Promise((resolve,reject)=>{
    // This is the executor block
    // This block will get executed as soon as the promise object is created
    // The arguments reject and resolve are callbacks provided by javascript itself
    // Our code only resides in this promise block
    // When the executor obtains the result, be it soon or late, doesn't matter, it should call one of the two functions
    // resolve(value) if the job is completed successfully with the value
    // reject(error) if an error has occured. "error" is the error object.

// To summarize the executor runs automatically and attemps to complete a job. When its finished with the attempt, it calls resolve with the value if successful or it returns a reject if there was an error
    // The promise object created by the new Promise() constructor has these internal properties
    // 1. state- initially "pending", then changes to "fulfilled" when resolve is called or "rejected" if reject is called
  // result- initially undefined, then changes to value when resolve is called or error when reject(error) is called.


      // setTimeout(()=> {
      //   // resolve("done");
      //   reject(new Error("Go fuck yourself you queer"));
      //   console.log("This is after the promise has resolved");
      //   // console.log("state: ",promise.state);
      //   // console.log("result: ",promise.result)
      //   console.log(promise)
        
      // },2000);

  // We can also resolve/reject a promisse immidietly if we dont want to do something asynchronous
  // The properties state and result of the promise object are internal. We cant access them directly
  // We can use the methods .then() .catch() and .finally() to access them.
    
  // })


  // Consumers: then, catch
  // A promise object acts as a link between the executor and and the consuming functions
  // Consuming functions can be registered/subscribed using methods .then and .catch

  // The most fundamental one is .then
  // promise.then((result)=>{
  //   // The first argument of the function is the function that is run when the promise is resolved
  //   console.log(result);
  // })
  // promise.catch(alert);
  // The above is syntactic sugar for .then(null,errorHandlingFunction)
  // The error message will be passed to the error handling function. Or will it?
  // promise.then(null,alert)



  // Let's clean up
  // Finally
  // The call .finally is the same as .then(f,f) that means that run it in any case ie. in case of both success or failure
  // The idea for sinally is to set up a handler for performing cleanup/finalizing after the previous operatins are complete
  // Eg. Closing no longer needed connections
  // promise.finally(()=>console.log("finally called"))
  // promise.catch(alert)
  // In the above execution .catch is called first then finally is called after the promise is either resolved or rejected
  
  // Do note that finally isnt exactly the same as .then(f,f)
  // These are the important differences
  // 1. The finally handler takes no arguments. In finally we dont whetehr the promise is successful or not
  // 2. That's all right. our tasks is to perform "general" finalizing procedures. Finally has no arguments and the promise outcome is handled in the next handler
  // 3. A finally handler passes through the result or error to the next suitable handler
  // For example here the result is passed through finally to the next .then
  // new Promise((resolve,reject)=>{
  //   setTimeout(()=>reject(new Error("There is a fucking error")),2000);
  // }).finally(()=>{
  //   console.log("finally called");
    
  // }).then(result=>console.log("This is the resulting value:",result)).catch(alert);
  // We observe in the above code that finally was called befor then and the value of the resulve was "passed though" finally to the next .then 




  // A finally handler should also not return anything. If it does then that return value is silently ignored.
  // When finally throws an error then the execution goes to the next handler
  
  
  // We can attach handlers to resolved promises

  // let promise = new Promise(resolve=> resolve("value"))


  // promise.then(alert)


  // Lets write the loadScript function using promises
  function loadScript(src){
    return new Promise((resolve,reject)=>{

      let script = document.createElement("script");
      script.src = src;

      // Resolve/reject the promise in when the page loads or ehen it does not load ie throws an error
      script.onload = resolve(script);
      script.onerror = reject(new Error());

      document.head.append(script);
  

      
    })
  }
  // Why isnt the checker function working in the below case
  // loadScript('/sample.js').then(()=>checkerFunction()).catch(alert);
  // The below code works but why
  // And why does the checker function code above doesnt work
  // Has the browser not loaded the page even after the onload hook
  // What seems to be the problem. I just dint understand. But lets move in for now.
  // loadScript('/sample.js').then(()=>alert("lets check if this sis working")).catch(alert);



  // Write setTimeout using promises
  function delay(ms){
    return new Promise((resolve,reject)=>{
      setTimeout(resolve,ms);
    })
  }

  // delay(3000).then(()=>console.log("value"));

  // console.log(a);
  // var a;
  // The above variable decalration is truly hoisted



  // Event bubbling and capturing are the two ways of event propagation in a dom tree. The Event capture falg which is the third parameter in the addEventListener method is used to select which of the two modes of event propagation will be used. The default method of propagation is bubbling but we can change it to capturing by seeting this flag to true.



  // Now lets look into debouncing

  let counter = 0;
  function getData(){
    // calls an api and gets data
    // The below api mock method is called counter number of times
    // We want to call it only when we pause while typing
    console.log(".... fetching data",++counter);
  }




  
  const doSomeMagic = function (method,delay){
    let timer;
    return function(){
      let context = this, args = arguments;
      // How is this timer being removed
      // Is this not a different instance?
      clearTimeout(timer); 
      timer = setTimeout(()=>{
        getData.apply(context,args)
      },delay)
    }
  }

  // let betterFunction = doSomeMagic(getData,300);
  // The above process of cancelling events if they are made in a very short time frame is called debouncing.
  // The way to do this 
  
  


  function check(event){
    // event.preventDefault();
    if(isNaN(event.target.value%2)){
      // console.log("jbdfbkdjf")
      console.log("Not a number")
      event.target.value = ""
    }
    // if((event.target.value%2)==NaN){
    //   console.log("dbjfbskjdbfkj")
    //   event.target.value=123;
    // }   
    // let element = event.srcElement;
    // console.log(element.textContent)
  }



  const Person = {
    firstname:"dsfds",
    lastname:"dsfdsfdszsezsez",
    sample:function(){
      console.log(this.firstname+" "+"lastname")
    }
    
  }

  Person.sample()


  // function person(){
  //   this.firstname="dssfsf";
  //   this.lastname="hbdfbgerf"
  //   this.fullname = function(){
  //     console.log(this.firstName+" "+this.lastname)
  //   }
  // }

  // new person().fullname()



  








  
  
  
  






  
</script>
</body>
</html>